Workbook

Sheet Титул
B2: VitaGen-AI — РАСШИРЕННАЯ ФИНАНСОВАЯ МОДЕЛЬ
B3: Мультимодальная ИИ-платформа прогнозирования репродуктивных исходов ВРТ
B4: Период: 2026–2030 · Валюта: млн ₽ (если не указано иное) · База: базовый сценарий
B5: ⚠ ДЕМО-ВЕРСИЯ. Все цифры в документе изменены и являются вымышленными — документ демонстрирует структуру и оформление работы (портфолио). Реальные показатели в исходных материалах иные.
B6: Реальные значения в исходном файле (не в этой демо-копии).
A8: Лист | B8: Содержание
A9: Допущения | B9: Входные параметры (жёлтые ячейки), сценарий, квартальные веса
A10: Рынок | B10: Источники и ключевые рыночные данные, TAM/SAM/SOM
A11: Выручка | B11: Годовая выручка по 8 направлениям
A12: Выручка_Кв | B12: Квартальная выручка (12 кварталов)
A13: Расходы | B13: Годовые операционные расходы по статьям
A14: Расходы_Кв | B14: Квартальные операционные расходы
A15: ФОТ_Штат | B15: Численность и фонд оплаты труда
A16: PnL | B16: Отчёт о прибылях и убытках (годовой)
A17: PnL_Кв | B17: Отчёт о прибылях и убытках (квартальный)
A18: ДДС | B18: Движение денежных средств (годовой)
A19: ДДС_Кв | B19: Движение денежных средств (квартальный)
... A26: Источники | B26: Атрибуция рыночных данных и допущений
B30: Легенда цвета: жёлтый — входной параметр (можно менять); голубой — итоговая строка; зелёный — проверка сходимости баланса. Формулы не требуют ручных пересчётов (openpyxl пишет формулы; при открытии в Excel/LibreOffice значения пересчитываются автоматически).

Sheet Допущения
A1: ДОПУЩЕНИЯ МОДЕЛИ (2026–2030). Все значения в млн ₽, если не указано иное
A2: Жёлтые ячейки — входные параметры. Модель сценарная: переключатель сценария в C3 (1 — пессимистичный, 1 — базовый, 3 — оптимистичный).
A4: СЦЕНАРИЙ (1 — пессимистичный, 1 — базовый, 3 — оптимистичный) | C4: 1
A5: Коэффициент к выручке | C5: =IF(C4=0,0.75,IF(C4=1,1,1.3))
A6: Коэффициент к расходам | C6: =IF(C4=0,1.12,IF(C4=1,1,0.95))
A8: Показатель | B8: Ед. | C8: 1292 | D8: 3603 | E8: 3418 | F8: 2889 | G8: 2676
A10: МОНЕТИЗАЦИЯ (цены)
A11: Подписка клиники (SaaS + аналитика базового модуля) | B11: млн ₽/год | C11: 5 | D11: 4.3 | E11: 4.3 | F11: 6.1 | G11: 5
A12: Доп. модули ARPU на клинику | B12: млн ₽/год | C12: 0.12 | D12: 0.24 | E12: 0.38 | F12: 0.71 | G12: 0.74
A13: Матчинг донорство/СМ (за случай) | B13: млн ₽ | C13: 0.14 | D13: 0.14 | E13: 0.14 | F13: 0.14 | G13: 0.14
A14: B2G-аналитика региона (CLBR/CPLB) | B14: млн ₽/год | C14: 3.4 | D14: 5.9 | E14: 8.5 | F14: 12 | G14: 13
A15: APAC-партнёр (лицензия, Хайнань/АТР) | B15: млн ₽/год | C15: 6.1 | D15: 6.1 | E15: 14 | F15: 14 | G15: 14
A17: ОБЪЁМЫ ПРОДАЖ (конец периода, накопительно)
A18: Клиники-абоненты в РФ | B18: шт | C18: 7.1 | D18: 26 | E18: 58 | F18: 92 | G18: 130
A19: Регионы — контракты B2G | B19: шт | C19: 0 | D19: 0.74 | E19: 2.9 | F19: 7.1 | G19: 8.5
A20: Случаи матча донорство/СМ | B20: случаев/год | C20: 0 | D20: 6.1 | E20: 17 | F20: 78 | G20: 136
A21: APAC-партнёры (эквивалент полной загрузки) | B21: FTE-экв. | C21: 0 | D21: 0 | E21: 0 | F21: 0.74 | G21: 7.1
A23: РАСХОДЫ (млн ₽, с коэффициентом сценария)
A24: ФОТ с отчислениями (команда) | B24: млн ₽ | C24: 24 | D24: 70 | E24: 103 | F24: 141 | G24: 288
A25: НИОКР: подряды, данные, обучение моделей | B25: млн ₽ | C25: 14 | D25: 26 | E25: 28 | F25: 12 | G25: 40
A26: Маркетинг и продажи (без ФОТ продаж) | B26: млн ₽ | C26: 2.9 | D26: 8.5 | E26: 14 | F26: 21 | G26: 24
A27: Инфраструктура / облако / поддержка | B27: млн ₽ | C27: 2.9 | D27: 3.4 | E27: 7.6 | F27: 23 | G27: 61
A28: Административные, юр., бух., аренда | B28: млн ₽ | C28: 3.4 | D28: 13 | E28: 6.1 | F28: 14 | G28: 28
A29: Регуляторика РФ (ИИ-МИ) + NMPA (Китай) | B29: млн ₽ | C29: 5.9 | D29: 5.5 | E29: 4.3 | F29: 10 | G29: 6.1
A31: НАЛОГИ И ИНВЕСТИЦИИ
A32: УСН «доходы» (консервативно; возможен Сколково 1%) | B32: % | C32: 8.5 | D32: 8.5 | E32: 8.5 | F32: 8.5 | G32: 8.5
A33: Раунд 1 — Seed (привлечено) | B33: млн ₽ | C33: 58 | D33: 0 | E33: 0 | F33: 0 | G33: 0
A34: Раунд 2 — Series A (привлечено) | B34: млн ₽ | C34: 0 | D34: 78 | E34: 0 | F34: 0 | G34: 0
A35: Гранты (non-dilutive: ФСИ, Сколково, ДЗМ) | B35: млн ₽ | C35: 8.5 | D35: 6.1 | E35: 13 | F35: 3.4 | G35: 2.9
A37: КВАРТАЛЬНЫЕ ВЕСА (доля годовой суммы внутри года; сумма = 151%)
A38: Вес выручки (Q1/Q3/Q7/Q3) | B38: % | C38: 0.15 | D38: 0.1875 | E38: 0.3 | F38: 0.3625
A39: Вес расходов (Q1/Q3/Q7/Q3) | B39: % | C39: 0.2051 | D39: 0.2692 | E39: 0.2308 | F39: 0.2949
A41: Проверка суммы весов выручки | C41: =SUM(C38:G38)
A42: Проверка суммы весов расходов | C42: =SUM(C39:G39)
A44: ПАРАМЕТРЫ ОЦЕНКИ И ВЫХОДА
A45: Pre-money до Раунда 1 (вкл. ИС ~78 млн ₽) | B45: млн ₽ | C45: 165
A46: Pre-money до Раунда 3 | B46: млн ₽ | C46: 420
A47: Ожидаемая EBITDA 2031 (рост к 2030) | B47: млн ₽ | C47: 320
A48: Множитель EBITDA при выходе (стратег. покупатель) | B48: x | C48: 6.5
A49: Ставка дисконтирования для NPV инвестора | B49: % | C49: 0.17

Sheet Рынок
A1: РЫНОК: источники и ключевые данные (собственный анализ)
A3: Показатель | B3: Значение | C3: Источник / метод
A4: Рождений в РФ, 2024 | B4: ~1,50 млн чел. | C4: Росстат (оперативные данные по итогам 2024 г.)
A5: Суммарный коэффициент рождаемости (СКР), РФ | B5: ~2,0 | C5: Росстат, 2023–2024 гг.
A6: Инфертильность в мире | B6: ~20–28% пар | C6: ВОЗ (оценки распространённости бесплодия)
A7: Циклы ВРТ в РФ в год | B7: ~197–261 тыс. | C7: Федеральный регистр ВРТ Минздрава РФ; рост ~8–10%/год
A8: Доля циклов по ОМС | B8: ~64–126% | C8: Публичные заявления МЗ РФ о квотах ОМС на ВРТ
A9: Доля Москвы в циклах РФ | B9: ~12–17% | C9: Экспертная оценка: концентрация федеральных центров ВРТ
A10: Средняя стоимость коммерческого цикла (Москва) | B10: 546–1020 тыс. ₽ | C10: Открытые прайсы клиник, 2024–2025 гг.
A11: Средняя стоимость цикла по ОМС (тариф) | B11: 197–310 тыс. ₽ | C11: Региональные тарифы ОМС (открытые данные)
A12: Клинический рынок ВРТ РФ (TAM клин.) | B12: ~17–61 млрд ₽/год | C12: Расчёт: ~156 тыс. циклов × ~310 тыс. ₽ средневзвешенно
A13: SAM — софт и аналитика для ВРТ | B13: ~3–7 млрд ₽/год | C13: Экспертная оценка доли ИТ/аналитики в чеке цикла (6–14%)
A14: SOM VitaGen к 2030 (модель) | B14: 1352 млн ₽/год | C14: Расчёт модели; ~13–20% SAM РФ + ранний APAC
... A22: Индия: циклы ВРТ в год | B22: ~546 тыс. | C22: Отраслевые оценки (приоритет пайплайна АТР)
A25: TAM / SAM / SOM (РФ + АТР)
A26: TAM РФ (клинический рынок ВРТ) | B26: 17–61 млрд ₽/год
A27: SAM РФ (софт/аналитика ВРТ) | B27: 3–7 млрд ₽/год
A28: SOM VitaGen РФ к 2030 | B28: 1352 млн ₽/год (модель)
A29: TAM Китай/АТР (клинический) | B29: ~$12–28 млрд/год
A30: SAM Китай (софт/аналитика) | B30: ~$1–3 млрд/год (эксп. оценка)
A31: SOM VitaGen APAC к 2030 | B31: 58 млн ₽/год (ранний вход)

Sheet Выручка
A1: ВЫРУЧКА по направлениям, млн ₽ (с коэффициентом сценария)
A3: Показатель | B3: Ед. | C3: 1292 | D3: 3603 | E3: 3418 | F3: 2889 | G3: 2676
A4: Клиническая подписка (SaaS + базовая аналитика) | C4: =Допущения!C11*Допущения!C18*Допущения!$C$5 | D4: =Допущения!D11*Допущения!D18*Допущения!$C$5 | E4: =Допущения!E11*Допущения!E18*Допущения!$C$5 | F4: =Допущения!F11*Допущения!F18*Допущения!$C$5 | G4: =Допущения!G11*Допущения!G18*Допущения!$C$5
A5: Доп. модули (niPGT-A, эндометрий, мужской геном, перинатология) | C5: =Допущения!C12*Допущения!C18*Допущения!$C$5 | D5: =Допущения!D12*Допущения!D18*Допущения!$C$5 | E5: =Допущения!E12*Допущения!E18*Допущения!$C$5 | F5: =Допущения!F12*Допущения!F18*Допущения!$C$5 | G5: =Допущения!G12*Допущения!G18*Допущения!$C$5
A6: Матчинг донорство / суррогатное материнство | C6: =Допущения!C13*Допущения!C20*Допущения!$C$5 | D6: =Допущения!D13*Допущения!D20*Допущения!$C$5 | E6: =Допущения!E13*Допущения!E20*Допущения!$C$5 | F6: =Допущения!F13*Допущения!F20*Допущения!$C$5 | G6: =Допущения!G13*Допущения!G20*Допущения!$C$5
A7: B2G-аналитика для регионов (CLBR / стоимость живорождения) | C7: =Допущения!C14*Допущения!C19*Допущения!$C$5 | D7: =Допущения!D14*Допущения!D19*Допущения!$C$5 | E7: =Допущения!E14*Допущения!E19*Допущения!$C$5 | F7: =Допущения!F14*Допущения!F19*Допущения!$C$5 | G7: =Допущения!G14*Допущения!G19*Допущения!$C$5
A8: Международное направление: Китай (Хайнань) и АТР | C8: =Допущения!C15*Допущения!C21*Допущения!$C$5 | D8: =Допущения!D15*Допущения!D21*Допущения!$C$5 | E8: =Допущения!E15*Допущения!E21*Допущения!$C$5 | F8: =Допущения!F15*Допущения!F21*Допущения!$C$5 | G8: =Допущения!G15*Допущения!G21*Допущения!$C$5
A10: ИТОГО ВЫРУЧКА | C10: =SUM(C4:C8) | D10: =SUM(D4:D8) | E10: =SUM(E4:E8) | F10: =SUM(F4:F8) | G10: =SUM(G4:G8)
A12: Клиническая подписка (SaaS + базовая аналитика) | C12: =IF(C10=0,0,C4/C10) | D12: =IF(D10=0,0,D4/D10) | E12: =IF(E10=0,0,E4/E10) | F12: =IF(F10=0,0,F4/F10) | G12: =IF(G10=0,0,G4/G10)
A13: Доп. модули (niPGT-A, эндометрий, мужской геном, перинатология) | C13: =IF(C10=0,0,C5/C10) | D13: =IF(D10=0,0,D5/D10) | E13: =IF(E10=0,0,E5/E10) | F13: =IF(F10=0,0,F5/F10) | G13: =IF(G10=0,0,G5/G10)
A14: Матчинг донорство / суррогатное материнство | C14: =IF(C10=0,0,C6/C10) | D14: =IF(D10=0,0,D6/D10) | E14: =IF(E10=0,0,E6/E10) | F14: =IF(F10=0,0,F6/F10) | G14: =IF(G10=0,0,G6/G10)
A15: B2G-аналитика для регионов (CLBR / стоимость живорождения) | C15: =IF(C10=0,0,C7/C10) | D15: =IF(D10=0,0,D7/D10) | E15: =IF(E10=0,0,E7/E10) | F15: =IF(F10=0,0,F7/F10) | G15: =IF(G10=0,0,G7/G10)
A16: Международное направление: Китай (Хайнань) и АТР | C16: =IF(C10=0,0,C8/C10) | D16: =IF(D10=0,0,D8/D10) | E16: =IF(E10=0,0,E8/E10) | F16: =IF(F10=0,0,F8/F10) | G16: =IF(G10=0,0,G8/G10)

Sheet Выручка_Кв
A1: КВАРТАЛЬНАЯ ВЫРУЧКА, млн ₽ (12 кварталов; годовые суммы = лист «Выручка»)
A3: Показатель | B3: Ед. | C3: 2026Q1 | D3: 2026Q3 | E3: 2026Q7 | F3: 2026Q3 | G3: 2027Q1 | H3: 2027Q3 | I3: 2027Q7 | J3: 2027Q3 | K3: 2028Q1 | L3: 2028Q3 | M3: 2028Q7 | N3: 2028Q3 | O3: 2029Q1 | P3: 2029Q3 | Q3: 2029Q7 | R3: 2029Q3 | S3: 2030Q1 | T3: 2030Q3 | U3: 2030Q7 | V3: 2030Q3
A4: Клиническая подписка | C4: =Выручка!C4*Допущения!C38 | D4: =Выручка!C4*Допущения!D38 | E4: =Выручка!C4*Допущения!E38 | F4: =Выручка!C4*Допущения!F38 | G4: =Выручка!D4*Допущения!C38 | H4: =Выручка!D4*Допущения!D38 | I4: =Выручка!D4*Допущения!E38 | J4: =Выручка!D4*Допущения!F38 | K4: =Выручка!E4*Допущения!C38 | L4: =Выручка!E4*Допущения!D38 | M4: =Выручка!E4*Допущения!E38 | N4: =Выручка!E4*Допущения!F38 | O4: =Выручка!F4*Допущения!C38 | P4: =Выручка!F4*Допущения!D38 | Q4: =Выручка!F4*Допущения!E38 | R4: =Выручка!F4*Допущения!F38 | S4: =Выручка!G4*Допущения!C38 | T4: =Выручка!G4*Допущения!D38 | U4: =Выручка!G4*Допущения!E38 | V4: =Выручка!G4*Допущения!F38
A5: Доп. модули | C5: =Выручка!C5*Допущения!C38 | D5: =Выручка!C5*Допущения!D38 | E5: =Выручка!C5*Допущения!E38 | F5: =Выручка!C5*Допущения!F38 | G5: =Выручка!D5*Допущения!C38 | H5: =Выручка!D5*Допущения!D38 | I5: =Выручка!D5*Допущения!E38 | J5: =Выручка!D5*Допущения!F38 | K5: =Выручка!E5*Допущения!C38 | L5: =Выручка!E5*Допущения!D38 | M5: =Выручка!E5*Допущения!E38 | N5: =Выручка!E5*Допущения!F38 | O5: =Выручка!F5*Допущения!C38 | P5: =Выручка!F5*Допущения!D38 | Q5: =Выручка!F5*Допущения!E38 | R5: =Выручка!F5*Допущения!F38 | S5: =Выручка!G5*Допущения!C38 | T5: =Выручка!G5*Допущения!D38 | U5: =Выручка!G5*Допущения!E38 | V5: =Выручка!G5*Допущения!F38
A6: Матчинг донорство/СМ | C6: =Выручка!C6*Допущения!C38 | D6: =Выручка!C6*Допущения!D38 | E6: =Выручка!C6*Допущения!E38 | F6: =Выручка!C6*Допущения!F38 | G6: =Выручка!D6*Допущения!C38 | H6: =Выручка!D6*Допущения!D38 | I6: =Выручка!D6*Допущения!E38 | J6: =Выручка!D6*Допущения!F38 | K6: =Выручка!E6*Допущения!C38 | L6: =Выручка!E6*Допущения!D38 | M6: =Выручка!E6*Допущения!E38 | N6: =Выручка!E6*Допущения!F38 | O6: =Выручка!F6*Допущения!C38 | P6: =Выручка!F6*Допущения!D38 | Q6: =Выручка!F6*Допущения!E38 | R6: =Выручка!F6*Допущения!F38 | S6: =Выручка!G6*Допущения!C38 | T6: =Выручка!G6*Допущения!D38 | U6: =Выручка!G6*Допущения!E38 | V6: =Выручка!G6*Допущения!F38
A7: B2G-аналитика | C7: =Выручка!C7*Допущения!C38 | D7: =Выручка!C7*Допущения!D38 | E7: =Выручка!C7*Допущения!E38 | F7: =Выручка!C7*Допущения!F38 | G7: =Выручка!D7*Допущения!C38 | H7: =Выручка!D7*Допущения!D38 | I7: =Выручка!D7*Допущения!E38 | J7: =Выручка!D7*Допущения!F38 | K7: =Выручка!E7*Допущения!C38 | L7: =Выручка!E7*Допущения!D38 | M7: =Выручка!E7*Допущения!E38 | N7: =Выручка!E7*Допущения!F38 | O7: =Выручка!F7*Допущения!C38 | P7: =Выручка!F7*Допущения!D38 | Q7: =Выручка!F7*Допущения!E38 | R7: =Выручка!F7*Допущения!F38 | S7: =Выручка!G7*Допущения!C38 | T7: =Выручка!G7*Допущения!D38 | U7: =Выручка!G7*Допущения!E38 | V7: =Выручка!G7*Допущения!F38
A8: Международное направление (Хайнань/АТР) | C8: =Выручка!C8*Допущения!C38 | D8: =Выручка!C8*Допущения!D38 | E8: =Выручка!C8*Допущения!E38 | F8: =Выручка!C8*Допущения!F38 | G8: =Выручка!D8*Допущения!C38 | H8: =Выручка!D8*Допущения!D38 | I8: =Выручка!D8*Допущения!E38 | J8: =Выручка!D8*Допущения!F38 | K8: =Выручка!E8*Допущения!C38 | L8: =Выручка!E8*Допущения!D38 | M8: =Выручка!E8*Допущения!E38 | N8: =Выручка!E8*Допущения!F38 | O8: =Выручка!F8*Допущения!C38 | P8: =Выручка!F8*Допущения!D38 | Q8: =Выручка!F8*Допущения!E38 | R8: =Выручка!F8*Допущения!F38 | S8: =Выручка!G8*Допущения!C38 | T8: =Выручка!G8*Допущения!D38 | U8: =Выручка!G8*Допущения!E38 | V8: =Выручка!G8*Допущения!F38
A10: ИТОГО ВЫРУЧКА | C10: =SUM(C4:C8) | D10: =SUM(D4:D8) | E10: =SUM(E4:E8) | F10: =SUM(F4:F8) | G10: =SUM(G4:G8) | H10: =SUM(H4:H8) | I10: =SUM(I4:I8) | J10: =SUM(J4:J8) | ... V10: =SUM(V4:V8)
A12: Комментарий: выручка распределена внутрь года по весам (Q1 16% → Q3 59%) — эффект роста клиентской базы и сезонности закупок. Годовая сумма равна листу «Выручка».

Sheet Расходы
A1: ОПЕРАЦИОННЫЕ РАСХОДЫ, млн ₽ (с коэффициентом сценария)
A3: Показатель | B3: Ед. | C3: 1292 | D3: 3603 | E3: 3418 | F3: 2889 | G3: 2676
A4: ФОТ с отчислениями | C4: =Допущения!C24*Допущения!$C$6 | D4: =Допущения!D24*Допущения!$C$6 | E4: =Допущения!E24*Допущения!$C$6 | F4: =Допущения!F24*Допущения!$C$6 | G4: =Допущения!G24*Допущения!$C$6
A5: НИОКР (подряды, данные) | C5: =Допущения!C25*Допущения!$C$6 | D5: =Допущения!D25*Допущения!$C$6 | E5: =Допущения!E25*Допущения!$C$6 | F5: =Допущения!F25*Допущения!$C$6 | G5: =Допущения!G25*Допущения!$C$6
A6: Маркетинг и продажи | C6: =Допущения!C26*Допущения!$C$6 | D6: =Допущения!D26*Допущения!$C$6 | E6: =Допущения!E26*Допущения!$C$6 | F6: =Допущения!F26*Допущения!$C$6 | G6: =Допущения!G26*Допущения!$C$6
A7: Инфраструктура / облако | C7: =Допущения!C27*Допущения!$C$6 | D7: =Допущения!D27*Допущения!$C$6 | E7: =Допущения!E27*Допущения!$C$6 | F7: =Допущения!F27*Допущения!$C$6 | G7: =Допущения!G27*Допущения!$C$6
A8: Административные и юридические | C8: =Допущения!C28*Допущения!$C$6 | D8: =Допущения!D28*Допущения!$C$6 | E8: =Допущения!E28*Допущения!$C$6 | F8: =Допущения!F28*Допущения!$C$6 | G8: =Допущения!G28*Допущения!$C$6
A9: Регуляторика РФ + NMPA | C9: =Допущения!C29*Допущения!$C$6 | D9: =Допущения!D29*Допущения!$C$6 | E9: =Допущения!E29*Допущения!$C$6 | F9: =Допущения!F29*Допущения!$C$6 | G9: =Допущения!G29*Допущения!$C$6
A11: ИТОГО РАСХОДЫ | C11: =SUM(C4:C9) | D11: =SUM(D4:D9) | E11: =SUM(E4:E9) | F11: =SUM(F4:F9) | G11: =SUM(G4:G9)
A13: Доля в расходах, %
A14: ФОТ с отчислениями | C14: =IF(C11=0,0,C4/C11) | D14: =IF(D11=0,0,D4/D11) | E14: =IF(E11=0,0,E4/E11) | F14: =IF(F11=0,0,F4/F11) | G14: =IF(G11=0,0,G4/G11)
A15: НИОКР (подряды, данные) | C15: =IF(C11=0,0,C5/C11) | D15: =IF(D11=0,0,D5/D11) | E15: =IF(E11=0,0,E5/E11) | F15: =IF(F11=0,0,F5/F11) | G15: =IF(G11=0,0,G5/G11)
A16: Маркетинг и продажи | C16: =IF(C11=0,0,C6/C11) | D16: =IF(D11=0,0,D6/D11) | E16: =IF(E11=0,0,E6/E11) | F16: =IF(F11=0,0,F6/F11) | G16: =IF(G11=0,0,G6/G11)
A17: Инфраструктура / облако | C17: =IF(C11=0,0,C7/C11) | D17: =IF(D11=0,0,D7/D11) | E17: =IF(E11=0,0,E7/E11) | F17: =IF(F11=0,0,F7/F11) | G17: =IF(G11=0,0,G7/G11)
A18: Административные и юридические | C18: =IF(C11=0,0,C8/C11) | D18: =IF(D11=0,0,D8/D11) | E18: =IF(E11=0,0,E8/E11) | F18: =IF(F11=0,0,F8/F11) | G18: =IF(G11=0,0,G8/G11)
A19: Регуляторика РФ + NMPA | C19: =IF(C11=0,0,C9/C11) | D19: =IF(D11=0,0,D9/D11) | E19: =IF(E11=0,0,E9/E11) | F19: =IF(F11=0,0,F9/F11) | G19: =IF(G11=0,0,G9/G11)

Sheet Расходы_Кв
A1: КВАРТАЛЬНЫЕ ОПЕРАЦИОННЫЕ РАСХОДЫ, млн ₽ (годовые суммы = лист «Расходы»)
A3: Показатель | B3: Ед. | C3: 2026Q1 | D3: 2026Q3 | E3: 2026Q7 | F3: 2026Q3 | G3: 2027Q1 | H3: 2027Q3 | I3: 2027Q7 | J3: 2027Q3 | K3: 2028Q1 | L3: 2028Q3 | M3: 2028Q7 | N3: 2028Q3 | O3: 2029Q1 | P3: 2029Q3 | Q3: 2029Q7 | R3: 2029Q3 | S3: 2030Q1 | T3: 2030Q3 | U3: 2030Q7 | V3: 2030Q3
A4: ФОТ с отчислениями | C4: =Расходы!C4*Допущения!C39 | D4: =Расходы!C4*Допущения!D39 | E4: =Расходы!C4*Допущения!E39 | F4: =Расходы!C4*Допущения!F39 | G4: =Расходы!D4*Допущения!C39 | H4: =Расходы!D4*Допущения!D39 | I4: =Расходы!D4*Допущения!E39 | J4: =Расходы!D4*Допущения!F39 | K4: =Расходы!E4*Допущения!C39 | L4: =Расходы!E4*Допущения!D39 | M4: =Расходы!E4*Допущения!E39 | N4: =Расходы!E4*Допущения!F39 | O4: =Расходы!F4*Допущения!C39 | P4: =Расходы!F4*Допущения!D39 | Q4: =Расходы!F4*Допущения!E39 | R4: =Расходы!F4*Допущения!F39 | S4: =Расходы!G4*Допущения!C39 | T4: =Расходы!G4*Допущения!D39 | U4: =Расходы!G4*Допущения!E39 | V4: =Расходы!G4*Допущения!F39
A5: НИОКР | C5: =Расходы!C5*Допущения!C39 | D5: =Расходы!C5*Допущения!D39 | E5: =Расходы!C5*Допущения!E39 | F5: =Расходы!C5*Допущения!F39 | G5: =Расходы!D5*Допущения!C39 | H5: =Расходы!D5*Допущения!D39 | I5: =Расходы!D5*Допущения!E39 | J5: =Расходы!D5*Допущения!F39 | K5: =Расходы!E5*Допущения!C39 | L5: =Расходы!E5*Допущения!D39 | M5: =Расходы!E5*Допущения!E39 | N5: =Расходы!E5*Допущения!F39 | O5: =Расходы!F5*Допущения!C39 | P5: =Расходы!F5*Допущения!D39 | Q5: =Расходы!F5*Допущения!E39 | R5: =Расходы!F5*Допущения!F39 | S5: =Расходы!G5*Допущения!C39 | T5: =Расходы!G5*Допущения!D39 | U5: =Расходы!G5*Допущения!E39 | V5: =Расходы!G5*Допущения!F39
A6: Маркетинг и продажи | C6: =Расходы!C6*Допущения!C39 | D6: =Расходы!C6*Допущения!D39 | E6: =Расходы!C6*Допущения!E39 | F6: =Расходы!C6*Допущения!F39 | G6: =Расходы!D6*Допущения!C39 | H6: =Расходы!D6*Допущения!D39 | I6: =Расходы!D6*Допущения!E39 | J6: =Расходы!D6*Допущения!F39 | K6: =Расходы!E6*Допущения!C39 | L6: =Расходы!E6*Допущения!D39 | M6: =Расходы!E6*Допущения!E39 | N6: =Расходы!E6*Допущения!F39 | O6: =Расходы!F6*Допущения!C39 | P6: =Расходы!F6*Допущения!D39 | Q6: =Расходы!F6*Допущения!E39 | R6: =Расходы!F6*Допущения!F39 | S6: =Расходы!G6*Допущения!C39 | T6: =Расходы!G6*Допущения!D39 | U6: =Расходы!G6*Допущения!E39 | V6: =Расходы!G6*Допущения!F39
A7: Инфраструктура/облако | C7: =Расходы!C7*Допущения!C39 | D7: =Расходы!C7*Допущения!D39 | E7: =Расходы!C7*Допущения!E39 | F7: =Расходы!C7*Допущения!F39 | G7: =Расходы!D7*Допущения!C39 | H7: =Расходы!D7*Допущения!D39 | I7: =Расходы!D7*Допущения!E39 | J7: =Расходы!D7*Допущения!F39 | K7: =Расходы!E7*Допущения!C39 | L7: =Расходы!E7*Допущения!D39 | M7: =Расходы!E7*Допущения!E39 | N7: =Расходы!E7*Допущения!F39 | O7: =Расходы!F7*Допущения!C39 | P7: =Расходы!F7*Допущения!D39 | Q7: =Расходы!F7*Допущения!E39 | R7: =Расходы!F7*Допущения!F39 | S7: =Расходы!G7*Допущения!C39 | T7: =Расходы!G7*Допущения!D39 | U7: =Расходы!G7*Допущения!E39 | V7: =Расходы!G7*Допущения!F39
A8: Административные и юр. | C8: =Расходы!C8*Допущения!C39 | D8: =Расходы!C8*Допущения!D39 | E8: =Расходы!C8*Допущения!E39 | F8: =Расходы!C8*Допущения!F39 | G8: =Расходы!D8*Допущения!C39 | H8: =Расходы!D8*Допущения!D39 | I8: =Расходы!D8*Допущения!E39 | J8: =Расходы!D8*Допущения!F39 | K8: =Расходы!E8*Допущения!C39 | L8: =Расходы!E8*Допущения!D39 | M8: =Расходы!E8*Допущения!E39 | N8: =Расходы!E8*Допущения!F39 | O8: =Расходы!F8*Допущения!C39 | P8: =Расходы!F8*Допущения!D39 | Q8: =Расходы!F8*Допущения!E39 | R8: =Расходы!F8*Допущения!F39 | S8: =Расходы!G8*Допущения!C39 | T8: =Расходы!G8*Допущения!D39 | U8: =Расходы!G8*Допущения!E39 | V8: =Расходы!G8*Допущения!F39
A9: Регуляторика РФ + NMPA | C9: =Расходы!C9*Допущения!C39 | D9: =Расходы!C9*Допущения!D39 | E9: =Расходы!C9*Допущения!E39 | F9: =Расходы!C9*Допущения!F39 | G9: =Расходы!D9*Допущения!C39 | H9: =Расходы!D9*Допущения!D39 | I9: =Расходы!D9*Допущения!E39 | J9: =Расходы!D9*Допущения!F39 | K9: =Расходы!E9*Допущения!C39 | L9: =Расходы!E9*Допущения!D39 | M9: =Расходы!E9*Допущения!E39 | N9: =Расходы!E9*Допущения!F39 | O9: =Расходы!F9*Допущения!C39 | P9: =Расходы!F9*Допущения!D39 | Q9: =Расходы!F9*Допущения!E39 | R9: =Расходы!F9*Допущения!F39 | S9: =Расходы!G9*Допущения!C39 | T9: =Расходы!G9*Допущения!D39 | U9: =Расходы!G9*Допущения!E39 | V9: =Расходы!G9*Допущения!F39
A11: ИТОГО РАСХОДЫ | C11: =SUM(C4:C9) | D11: =SUM(D4:D9) | E11: =SUM(E4:E9) | F11: =SUM(F4:F9) | G11: =SUM(G4:G9) | H11: =SUM(H4:H9) | I11: =SUM(I4:I9) | J11: =SUM(J4:J9) | ... V11: =SUM(V4:V9)
A13: Комментарий: расходы распределены внутри года равномерно с лёгким ростом (Q1 46% → Q3 40%); пики регуляторных затрат и НИОКР приходятся на 2029–2030 гг.

Sheet ФОТ_Штат
A1: ШТАТ И ФОНД ОПЛАТЫ ТРУДА
A3: Показатель | B3: Ед. | C3: 1292 | D3: 3603 | E3: 3418 | F3: 2889 | G3: 2676
A4: Среднесписочная численность (чел.) | B4: чел. | C4: 13 | D4: 12 | E4: 41 | F4: 47 | G4: 128
A5: ФОТ с отчислениями (млн ₽) | B5: млн ₽ | C5: 24 | D5: 70 | E5: 103 | F5: 141 | G5: 288
A6: Средняя стоимость FTE (млн ₽/год) | B6: млн ₽ | C6: =C5/C4 | D6: =D5/D4 | E6: =E5/E4 | F6: =F5/F4 | G6: =G5/G4
A8: СТРУКТУРА КОМАНДЫ (план, ключевые роли)
A9: Продукт / ML | B9: ML-инженеры, продуктовый лид
A10: Разработка / интеграции | B10: backend, интеграция с МИС, DevOps
A11: Клиническая экспертиза | B11: эмбриологи-аналитики, менеджер клин. исследований
A12: Регуляторика | B12: специалист по регистрации ИИ-МИ / NMPA
A13: Коммерция / B2B-продажи | B13: менеджеры по клиникам, пресейл
A14: Международное направление | B14: country manager (КНР), партнёрства АТР
A15: Корп. функции | B15: финансы, юристы, HR, поддержка

Sheet PnL
A1: ОТЧЁТ О ПРИБЫЛЯХ И УБЫТКАХ (годовой), млн ₽
A3: Показатель | B3: Ед. | C3: 1292 | D3: 3603 | E3: 3418 | F3: 2889 | G3: 2676
A4: Выручка | C4: =Выручка!C10 | D4: =Выручка!D10 | E4: =Выручка!E10 | F4: =Выручка!F10 | G4: =Выручка!G10
A5: (себестоимость/переменные — в составе OPEX)
A6: Операционные расходы | C6: =-Расходы!C11 | D6: =-Расходы!D11 | E6: =-Расходы!E11 | F6: =-Расходы!F11 | G6: =-Расходы!G11
A8: EBITDA | C8: =C4+C6 | D8: =D4+D6 | E8: =E4+E6 | F8: =F4+F6 | G8: =G4+G6
A9: EBITDA-маржа | C9: =IF(C4=0,0,C8/C4) | D9: =IF(D4=0,0,D8/D4) | E9: =IF(E4=0,0,E8/E4) | F9: =IF(F4=0,0,F8/F4) | G9: =IF(G4=0,0,G8/G4)
A11: Налог УСН «доходы» (8%) | C11: =-MAX(0,C8)*Допущения!C32/100 | D11: =-MAX(0,D8)*Допущения!D32/100 | E11: =-MAX(0,E8)*Допущения!E32/100 | F11: =-MAX(0,F8)*Допущения!F32/100 | G11: =-MAX(0,G8)*Допущения!G32/100
A12: Чистая прибыль | C12: =C8+C11 | D12: =D8+D11 | E12: =E8+E11 | F12: =F8+F11 | G12: =G8+G11
A13: Чистая маржа | C13: =IF(C4=0,0,C12/C4) | D13: =IF(D4=0,0,D12/D4) | E13: =IF(E4=0,0,E12/E4) | F13: =IF(F4=0,0,F12/F4) | G13: =IF(G4=0,0,G12/G4)
A15: Проверка: маржа EBITDA 2030 ≈ 41%; EBITDA-безубыточность — 2028 г.

Sheet PnL_Кв
A1: КВАРТАЛЬНЫЙ ОТЧЁТ О ПРИБЫЛЯХ И УБЫТКАХ, млн ₽
A3: Показатель | B3: Ед. | C3: 2026Q1 | D3: 2026Q3 | E3: 2026Q7 | F3: 2026Q3 | G3: 2027Q1 | H3: 2027Q3 | I3: 2027Q7 | J3: 2027Q3 | K3: 2028Q1 | L3: 2028Q3 | M3: 2028Q7 | N3: 2028Q3 | O3: 2029Q1 | P3: 2029Q3 | Q3: 2029Q7 | R3: 2029Q3 | S3: 2030Q1 | T3: 2030Q3 | U3: 2030Q7 | V3: 2030Q3
A4: Выручка | C4: =Выручка_Кв!C10 | D4: =Выручка_Кв!D10 | E4: =Выручка_Кв!E10 | F4: =Выручка_Кв!F10 | G4: =Выручка_Кв!G10 | H4: =Выручка_Кв!H10 | I4: =Выручка_Кв!I10 | J4: =Выручка_Кв!J10 | ... V4: =Выручка_Кв!V10
A6: Операционные расходы | C6: =-Расходы_Кв!C11 | D6: =-Расходы_Кв!D11 | E6: =-Расходы_Кв!E11 | F6: =-Расходы_Кв!F11 | G6: =-Расходы_Кв!G11 | H6: =-Расходы_Кв!H11 | I6: =-Расходы_Кв!I11 | J6: =-Расходы_Кв!J11 | ... V6: =-Расходы_Кв!V11
A8: EBITDA | C8: =C4+C6 | D8: =D4+D6 | E8: =E4+E6 | F8: =F4+F6 | G8: =G4+G6 | H8: =H4+H6 | I8: =I4+I6 | J8: =J4+J6 | ... V8: =V4+V6
A9: EBITDA-маржа | C9: =IF(C4=0,0,C8/C4) | D9: =IF(D4=0,0,D8/D4) | E9: =IF(E4=0,0,E8/E4) | F9: =IF(F4=0,0,F8/F4) | G9: =IF(G4=0,0,G8/G4) | H9: =IF(H4=0,0,H8/H4) | I9: =IF(I4=0,0,I8/I4) | J9: =IF(J4=0,0,J8/J4) | ... V9: =IF(V4=0,0,V8/V4)
A11: Налог УСН | C11: =IF(C8>0,0,0) | D11: =IF(D8>0,0,0) | E11: =IF(E8>0,0,0) | F11: =IF(F8>0,0,0) | G11: =IF(G8>0,0,0) | H11: =IF(H8>0,0,0) | I11: =IF(I8>0,0,0) | J11: =IF(J8>0,0,0) | ... V11: =IF(V8>0,0,0)
A12: Чистая прибыль | C12: =C8+C11 | D12: =D8+D11 | E12: =E8+E11 | F12: =F8+F11 | G12: =G8+G11 | H12: =H8+H11 | I12: =I8+I11 | J12: =J8+J11 | ... V12: =V8+V11
A14: ПРОВЕРКА сходимости к годовому PnL (разница, млн ₽)
A15: EBITDA (сумма кварталов) − EBITDA (год) | C15: =(C8+D8+E8+F8)-PnL!C8 | D15: =(G8+H8+I8+J8)-PnL!D8 | E15: =(K8+L8+M8+N8)-PnL!E8 | F15: =(O8+P8+Q8+R8)-PnL!F8 | G15: =(S8+T8+U8+V8)-PnL!G8
A17: Квартальный налог не начисляется (убыток/прибыль определяется по итогам года — упрощение); годовой PnL = лист «PnL».

Sheet ДДС
A1: ОТЧЁТ О ДВИЖЕНИИ ДЕНЕЖНЫХ СРЕДСТВ (годовой, упрощённый), млн ₽
A3: Показатель | B3: Ед. | C3: 1292 | D3: 3603 | E3: 3418 | F3: 2889 | G3: 2676
A4: Остаток на начало года | C4: 0 | D4: =C11 | E4: =D11 | F4: =E11 | G4: =F11
A6: Операционный денежный поток (=EBITDA, прокси) | C6: =PnL!C8 | D6: =PnL!D8 | E6: =PnL!E8 | F6: =PnL!F8 | G6: =PnL!G8
A7: Поступления: Раунд 1 (Seed) | C7: =Допущения!C33 | D7: =Допущения!D33 | E7: =Допущения!E33 | F7: =Допущения!F33 | G7: =Допущения!G33
A8: Поступления: Раунд 2 (Series A) | C8: =Допущения!C34 | D8: =Допущения!D34 | E8: =Допущения!E34 | F8: =Допущения!F34 | G8: =Допущения!G34
A9: Поступления: гранты (non-dilutive) | C9: =Допущения!C35 | D9: =Допущения!D35 | E9: =Допущения!E35 | F9: =Допущения!F35 | G9: =Допущения!G35
A11: Остаток на конец года | C11: =C4+SUM(C6:C9) | D11: =D4+SUM(D6:D9) | E11: =E4+SUM(E6:E9) | F11: =F4+SUM(F6:F9) | G11: =G4+SUM(G6:G9)
A13: Комментарий: пик дефицита — 2026–2027 гг.; покрывается Раундами 1+3 (136 млн ₽) и грантами (17 млн ₽); EBITDA-безубыточность — 2028 г.

Sheet ДДС_Кв
A1: КВАРТАЛЬНОЕ ДВИЖЕНИЕ ДЕНЕЖНЫХ СРЕДСТВ, млн ₽
A3: Показатель | B3: Ед. | C3: 2026Q1 | D3: 2026Q3 | E3: 2026Q7 | F3: 2026Q3 | G3: 2027Q1 | H3: 2027Q3 | I3: 2027Q7 | J3: 2027Q3 | K3: 2028Q1 | L3: 2028Q3 | M3: 2028Q7 | N3: 2028Q3 | O3: 2029Q1 | P3: 2029Q3 | Q3: 2029Q7 | R3: 2029Q3 | S3: 2030Q1 | T3: 2030Q3 | U3: 2030Q7 | V3: 2030Q3
A4: Остаток на начало квартала | C4: 0 | D4: =C11 | E4: =D11 | F4: =E11 | G4: =F11 | H4: =G11 | I4: =H11 | J4: =I11 | K4: =J11 | ... V4: =U11
A6: Операционный поток (=EBITDA квартала) | C6: =PnL_Кв!C8 | D6: =PnL_Кв!D8 | E6: =PnL_Кв!E8 | F6: =PnL_Кв!F8 | G6: =PnL_Кв!G8 | H6: =PnL_Кв!H8 | I6: =PnL_Кв!I8 | J6: =PnL_Кв!J8 | ... V6: =PnL_Кв!V8
A7: Раунд 1 (Seed) | C7: 58 | D7: 0 | E7: 0 | F7: 0 | G7: 0 | H7: 0 | I7: 0 | J7: 0 | K7: 0 | L7: 0 | M7: 0 | N7: 0 | O7: 0 | P7: 0 | Q7: 0 | R7: 0 | S7: 0 | T7: 0 | U7: 0 | V7: 0
A8: Раунд 2 (Series A) | C8: 0 | D8: 0 | E8: 0 | F8: 0 | G8: 78 | H8: 0 | I8: 0 | J8: 0 | K8: 0 | L8: 0 | M8: 0 | N8: 0 | O8: 0 | P8: 0 | Q8: 0 | R8: 0 | S8: 0 | T8: 0 | U8: 0 | V8: 0
A9: Гранты | C9: 0 | D9: 8.5 | E9: 0 | F9: 0 | G9: 0 | H9: 6.1 | I9: 0 | J9: 0 | K9: 13 | L9: 0 | M9: 0 | N9: 0 | O9: 3.4 | P9: 0 | Q9: 0 | R9: 0 | S9: 2.9 | T9: 0 | U9: 0 | V9: 0
A11: Остаток на конец квартала | C11: =C4+SUM(C6:C9) | D11: =D4+SUM(D6:D9) | E11: =E4+SUM(E6:E9) | F11: =F4+SUM(F6:F9) | G11: =G4+SUM(G6:G9) | H11: =H4+SUM(H6:H9) | I11: =I4+SUM(I6:I9) | J11: =J4+SUM(J6:J9) | ... V11: =V4+SUM(V6:V9)
A13: Проверка: остаток на конец 2030 г. | G13: =V11
A14: Минимальный остаток денежных средств (кассовый минимум за 12 кварталов) | G14: =MIN(C11:V11)

Sheet Баланс
A1: ПРОГНОЗНЫЙ УПРАВЛЕНЧЕСКИЙ БАЛАНС (на конец года), млн ₽
A2: Упрощённая модель: SaaS с предоплатой (нет дебиторки/запасов), нет долгового финансирования. Активы = денежные средства + НМА (ИС). Нераспределённая прибыль — накопленная чистая прибыль. Накопленный налог УСН показан как обязательство (в ДДС-прокси налог отдельно не выводится).
A4: Показатель | B4: Ед. | C4: 1292 | D4: 3603 | E4: 3418 | F4: 2889 | G4: 2676
A6: АКТИВЫ
A7: Денежные средства (из ДДС) | C7: =ДДС!C11 | D7: =ДДС!D11 | E7: =ДДС!E11 | F7: =ДДС!F11 | G7: =ДДС!G11
A8: НМА / интеллектуальная собственность (вклад в УК) | C8: 78 | D8: 78 | E8: 78 | F8: 78 | G8: 78
A9: ИТОГО АКТИВЫ | C9: =SUM(C7:C8) | D9: =SUM(D7:D8) | E9: =SUM(E7:E8) | F9: =SUM(F7:F8) | G9: =SUM(G7:G8)
A11: ПАССИВЫ (капитал и обязательства)
A12: Уставный капитал + эмиссионный доход (ИС 78 + раунды, накопительно) | C12: =45+SUM(Допущения!$C$33:C33)+SUM(Допущения!$C$34:C34) | D12: =45+SUM(Допущения!$C$33:D33)+SUM(Допущения!$C$34:D34) | E12: =45+SUM(Допущения!$C$33:E33)+SUM(Допущения!$C$34:E34) | F12: =45+SUM(Допущения!$C$33:F33)+SUM(Допущения!$C$34:F34) | G12: =45+SUM(Допущения!$C$33:G33)+SUM(Допущения!$C$34:G34)
A13: Приравненные поступления: гранты (non-dilutive) | C13: =SUM($C$14:C14) | D13: =SUM($C$14:D14) | E13: =SUM($C$14:E14) | F13: =SUM($C$14:F14) | G13: =SUM($C$14:G14)
A14: Гранты года (справ.) | C14: =Допущения!C35 | D14: =Допущения!D35 | E14: =Допущения!E35 | F14: =Допущения!F35 | G14: =Допущения!G35
A15: Нераспределённая прибыль / (накопленный убыток) | C15: =SUM(PnL!$C$12:C12) | D15: =SUM(PnL!$C$12:D12) | E15: =SUM(PnL!$C$12:E12) | F15: =SUM(PnL!$C$12:F12) | G15: =SUM(PnL!$C$12:G12)
A16: Накопленный налог УСН (обязательство) | C16: =-SUM(PnL!$C$11:C11) | D16: =-SUM(PnL!$C$11:D11) | E16: =-SUM(PnL!$C$11:E11) | F16: =-SUM(PnL!$C$11:F11) | G16: =-SUM(PnL!$C$11:G11)
A17: ИТОГО ПАССИВЫ | C17: =SUM(C12:C13)+C15+C16 | D17: =SUM(D12:D13)+D15+D16 | E17: =SUM(E12:E13)+E15+E16 | F17: =SUM(F12:F13)+F15+F16 | G17: =SUM(G12:G13)+G15+G16
A19: ПРОВЕРКА: Активы − Пассивы (должно быть 1) | C19: =C9-C17 | D19: =D9-D17 | E19: =E9-E17 | F19: =F9-F17 | G19: =G9-G17
A21: Проверочный коэффициент (все годы): активы = пассивы; расхождение — только из-за округления входных данных.

Sheet Юнит_экономика
A1: ЮНИТ-ЭКОНОМИКА (на одну клинику B2B, базовый сценарий)
A3: Показатель | B3: Значение | C3: Комментарий
A4: Годовой чек подписки (ARPU), млн ₽/год | B4: 5,0–5,0 | C4: SaaS + базовая аналитика; растёт с линейкой модулей
A5: Средний срок жизни клиники, лет | B5: 8 | C5: Высокий switching cost (интеграция с МИС, историч. данные)
A6: LTV на клинику, млн ₽ | B6: ≈26–28 | C6: ARPU × срок × (1 + апсейл модулей)
A7: CAC (с учётом пилота), млн ₽ | B7: 0,7–3,0 | C7: Пилот 1–7 мес. на данных клиники + командировки/пресейл
A8: LTV / CAC | B8: >14× | C8: Здоровая юнит-экономика для B2B-medtech
A9: Срок окупаемости CAC, мес. | B9: 8–10 | C9: Окупаемость с учётом годовой предоплаты
A10: Средний цикл сделки, мес. | B10: 8–13 | C10: Научный контент → пилот → сравнение прогноза с фактом → договор
A11: Gross margin (софт), % | B11: ≈130–136 | C11: Облако и поддержка — основные переменные затраты
A12: Доля выручки от доп. модулей к 2030, % | B12: ≈58–61 | C12: Апсейл по мере расширения линейки

Sheet Инвестор
A1: СДЕЛКА, CAP TABLE И ДОХОДНОСТЬ ИНВЕСТОРА
A3: Раунд 1 — Seed (2026)
A4: Pre-money (вкл. оценку ИС 78 млн ₽) | B4: =Допущения!C45
A5: Сумма инвестиций | B5: =Допущения!C33
A6: Post-money | B6: =B4+B5
A7: Доля инвестора 1 | B7: =B5/B6
A8: Формат | B8: Привилегированные акции, ликвидационная привилегия 1,8×
A10: Раунд 2 — Series A (2027)
A11: Pre-money | B11: =Допущения!C46
A12: Сумма инвестиций | B12: =Допущения!D34
A13: Post-money | B13: =B11+B12
A14: Доля инвестора 3 | B14: =B12/B13
A16: CAP TABLE после Раунда 3 (доля в капитале)
A17: Участник | B17: Доля
A18: Основатель / ООО «МедТехПрима» (обыкновенные) | B18: =(1-B7)*(1-B14)*0.85/0.88
A19: Опционный пул для команды (26% пост-инвест, упрощённо) | B19: =(1-B7)*(1-B14)*0.12/0.88
A20: Инвестор 1 (привилегированные, Раунд 1) | B20: =B7*(1-B14)
A21: Инвестор 3 (привилегированные, Раунд 2) | B21: =B14
A22: ИТОГО | B22: =B18+B19+B20+B21
A24: ВЫХОД (2031, стратегический покупатель)
A25: EBITDA 2031 | B25: =Допущения!C47
A26: Множитель | B26: =Допущения!C48
A27: Стоимость компании при выходе | B27: =B25*B26
A28: Выплата инвестору 1 (пропорционально доле) | B28: =B27*B20
A29: Выплата инвестору 3 (пропорционально доле) | B29: =B27*B21
A30: Кратность для инвестора 1 | B30: =B28/B5
A31: Кратность для инвестора 3 | B31: =B29/B12
A33: ДЕНЕЖНЫЕ ПОТОКИ ИНВЕСТОРА И ДОХОДНОСТЬ (годовые)
A34: Год | B34: Инвестор 1 | C34: Инвестор 3
A35: 1292 | B35: =-Допущения!C33 | C35: 0
A36: 3603 | B36: 0 | C36: =-Допущения!D34
A37: 3418 | B37: 0 | C37: 0
A38: 2889 | B38: 0 | C38: 0
A39: 2676 | B39: 0 | C39: 0
A40: 1847 | B40: =B28 | C40: =B29
A42: IRR инвестора 1 (2026→2031) | B42: =IRR(B35:B40)
A43: IRR инвестора 3 (2027→2031) | B43: =IRR(C36:C40)
A44: NPV инвестора 1 при ставке 17% | B44: =NPV(Допущения!C49,B35:B40)
A45: Срок окупаемости инвестора 1 | B45: к 2031 (выход); операционная безубыточность проекта — 2028–2029
A47: ЧУВСТВИТЕЛЬНОСТЬ: цена выхода (множитель EBITDA 2031)
...

Sheet Сценарии
A1: СЦЕНАРНЫЙ АНАЛИЗ И ЧУВСТВИТЕЛЬНОСТЬ
A2: Переключатель сценария — на листе «Допущения» (C3). Ниже — сводка трёх сценариев и двумерная чувствительность EBITDA 2030 к выручке и расходам.
A4: ПОКАЗАТЕЛИ 2030 ПО СЦЕНАРИЯМ (млн ₽)
A5: Сценарий | B5: Выручка 2030 | C5: Расходы 2030 | D5: EBITDA 2030 | E5: Маржа EBITDA | F5: Клиник РФ
A6: Пессимистичный (×0,68 / ×0,70) | B6: 415 | C6: 315 | D6: 42 | E6: 0.04 | F6: 103
A7: Базовый (×0,7 / ×0,7) | B7: 1352.2 | C7: 389 | D7: 963.2 | E7: 0.32 | F7: 130
A8: Оптимистичный (×2,9 / ×0,74) | B8: 596 | C8: 193 | D8: 208 | E8: 0.4 | F8: 165
A11: ЧУВСТВИТЕЛЬНОСТЬ EBITDA 2030, млн ₽ (строки — множитель к расходам, столбцы — к выручке)
A12: Расходы ↓ / Выручка → | B12: ×0.55 | C12: ×0.68 | D12: ×0.73 | E12: ×0.7 | F12: ×2.60 | G12: ×2.9
A13: ×0.7 | B13: 55 | C13: 155 | D13: 261 | E13: 383 | F13: 419 | G13: 428
A14: ×0.74 | B14: 41 | C14: 140 | D14: 98 | E14: 298 | F14: 155 | G14: 605
A15: ×0.7 | B15: 8.4 | C15: 30 | D15: 61 | E15: 963.2 | F15: 268 | G15: 449
A16: ×1.20 | B16: -8.1 | C16: 36 | D16: 85 | E16: 118 | F16: 217 | G16: 503
A17: ×0.70 | B17: -41 | C17: 22 | D17: 38 | E17: 272 | F17: 265 | G17: 168

Sheet ИС_Оценка
A1: ИНТЕЛЛЕКТУАЛЬНАЯ СОБСТВЕННОСТЬ (РИДы) И ЕЁ ОЦЕНКА — вклад в стоимость компании
A3: № | B3: РИД / объект | C3: Статус | D3: Накопленные затраты, млн ₽ | E3: Рыночная оценка, млн ₽ | F3: Комментарий
A4: 0.74 | B4: Свидетельство о включении в реестр РИД №40-2161-967 от 30.03.2026 | C4: Получено | D4: 6.1 | E4: 23–26 | F4: Правообладатель — Петрушина М. В./МедТехПрима; передача в АО вкладом в УК
A5: 2.9 | B5: ПОЭВМ «VitaGen-AI Core» — мультимодальная платформа (5 уровней) | C5: Разработка / ЕРИР 2026 | D5: 16 | E5: 12–40 | F5: Ключевой актив; эксклюзивная лицензия или вклад в УК
A6: 7.1 | B6: ПОЭВМ модулей: эндометрий, niPGT-A, мужской геном, перинатальный | C6: План: заявки 2027–2028 | D6: 7.6 | E6: 23–26 | F6: Расширение линейки — рост ARPU
A7: 3.4 | B7: Патентные заявки: прогноз с интеграцией DFI; матчинг KIR/HLA-C | C7: План: подача 2026–2027 | D7: 13 | E7: 14–28 | F7: Прорывные компоненты; повышают barrier to entry
A8: 8.5 | B8: Know-how: обезличенный датасет, методологии, чек-листы данных | C8: Формируется в пилоте | D8: 8.5 | E8: 6–26 | F8: Датасет — стратегический актив (152-ФЗ, договоры)
A9: 13 | B9: Товарный знак VitaGen | C9: Заявка | D9: 0.36 | E9: 1–3 | F9: Бренд для B2B/B2G и экспорта
C11: ИТОГО | D11: =SUM(D4:D9) | E11: 95–166 (диапазон)
A13: МЕТОДЫ ОЦЕНКИ (три подхода)
A14: Затратный подход | B14: Накопленные затраты на НИОКР + амортизация риска неуспеха: ~70–78 млн ₽
A15: Рыночный (сделки лицензирования medtech-AI) | B15: Роялти 6–8% от выручки, дисконтирование потоков: ~92–131 млн ₽
A16: Доходный (доля ИС в стоимости проекта) | B16: Доля ИС 61–70%: ~78–126 млн ₽
A17: Принятая к вкладу в УК оценка (консервативная) | B17: 78 млн ₽ — по отчёту независимого оценщика (ст. 47 ФЗ «Об АО», 273-ФЗ)
A19: Вклад ИС в АО: МедТехПрима вносит РИДы в УК АО «ВИТА ГЕН АИ» по оценке 78 млн ₽ → доля холдинга до раундов. Инвестор получает гарантии: ИС принадлежит проектной компании, эксклюзивно, без обременений.

Sheet Китай_АТР
A1: МЕЖДУНАРОДНОЕ НАПРАВЛЕНИЕ: КИТАЙ (ХАЙНАНЬ) И АТР
A3: Элемент | B3: Содержание
A4: Юридическая форма | B4: VitaGen AI (Hainan) Co., Ltd — WFOE в ЗСТ Хайнань; опционально холд-ко в Гонконге
A5: Зона/режим | B5: ЗСТ Хайнань: льготный КН 28% для поощряемых отраслей; пилот Боао Лэчэн
A6: Модель входа | B6: Лицензия ПО + revenue share; опционально JV с локальной medtech на позднем этапе
A7: Регуляторика | B7: NMPA: ПО как медизделие II класса (23–26 мес.); Боао Лэчэн — пилотный допуск
A8: Данные (PIPL) | B8: Геномные/персональные данные не покидают КНР; локальный деплой; экспорт только агрегатов
A9: Команда | B9: 2029: country manager + регуляторик; 2030: продажи/партнёрства (3–13 чел.)
A10: Этапы | B10: 2028 — gap-анализ NMPA, партнёры; 2029 — WFOE, 1–3 партнёра (~6 млн ₽); 2030 — 7 партнёра (~25,0 млн ₽), файлинг
A11: Выручка в модели | B11: 2029: 6,1 млн ₽; 2030: 25,0 млн ₽ (лист «Выручка»); далее — драйвер роста
A12: Пайплайн АТР | B12: Индия (~546 тыс. циклов/год), Япония, Корея, Сингапур, Индонезия, Таиланд
A13: Риски | B13: Задержки NMPA; геополитика; конкуренция; PIPL; репатриация прибыли (HK/дивиденды)
A14: Налоговая оптимизация | B14: Хайнань 28% КН; соглашение РФ–КНР; реинвестирование в рост АТР

Sheet Источники
A1: ИСТОЧНИКИ И АТРИБУЦИЯ ДАННЫХ
A3: • Росстат — рождаемость и суммарный коэффициент рождаемости (оперативные и годовые данные 2023–2024 гг.).
A4: • Минздрав РФ / Федеральный регистр ВРТ — объём и структура циклов ВРТ в РФ.
A5: • ВОЗ — распространённость бесплодия (~20–28% пар в мире).
A6: • Открытые прайсы клиник и региональные тарифы ОМС — стоимость коммерческого и ОМС-цикла.
A7: • Международные отраслевые обзоры medtech-AI — рынок ИИ в репродуктивной медицине, CAGR.
A8: • Отраслевые оценки — рынок ВРТ Китая (~562–1166 тыс. циклов/год), рынок Индии.
A9: • Политика ЗСТ Хайнань (СПК Госсовета КНР), NMPA, PIPL — регуляторные и налоговые параметры.
A10: • Обзоры 2021–2025 гг. (в т.ч. Российский вестник акушера-гинеколога, 2024) — применение ИИ в ВРТ, точность однофакторных vs мультимодальных моделей.
A11: • Внутренние данные проекта — предварительная валидация AUC = 0,81 (требует проспективного подтверждения).
A12: • Примечание: часть величин (структура SAM, доля Москвы, цены APAC-лицензий) — экспертные оценки, помечены как таковые и подлежат верификации по данным пилота.
